Workbook
Name lstCartoes: tbCartoes[Cartão]
Name lstCategorias: tbCategorias[Categoria]
Name lstGrupos: Categorias!$I$7:$I$10
Name lstMeses: Resumo!$B$7:$B$18
Name lstPagamento: Categorias!$J$7:$J$11
Name lstTipos: Categorias!$H$7:$H$9
Name lstTiposPatrimonio: Patrimônio!$P$6:$P$10

Sheet Painel
B2: Organização financeira | J2: PATRIMÔNIO LÍQUIDO | M2: MÊS DO PAINEL
B3: =IF(SUMPRODUCT((SUMIFS(tbLancamentos[Valor],tbLancamentos[Mês],$M$3,tbLancamentos[Descrição],tbContas[Conta])=0)*(DATE(YEAR($M$3),MONTH($M$3),tbContas[Dia do vencimento])<TODAY()))+$O$86+SUMPRODUCT((tbParcelas[1ª fatura]<=$M$3)*(tbParcelas[Última fatura]>=$M$3)*(COUNTIFS(tbLancamentos[Mês],$M$3,tbLancamentos[Descrição],tbParcelas[Descrição])=0))+($K$7<0)=0,"✓ Tudo em dia neste mês","⚠ "&IF(SUMPRODUCT((SUMIFS(tbLancamentos[Valor],tbLancamentos[Mês],$M$3,tbLancamentos[Descrição],tbContas[Conta])=0)*(DATE(YEAR($M$3),MONTH($M$3),tbContas[Dia do vencimento])<TODAY()))>0,SUMPRODUCT((SUMIFS(tbLancamentos[Valor],tbLancamentos[Mês],$M$3,tbLancamentos[Descrição],tbContas[Conta])=0)*(DATE(YEAR($M$3),MONTH($M$3),tbContas[Dia do vencimento])<TODAY()))&" conta(s) vencida(s) ","")&IF($O$86>0,$O$86&" categoria(s) acima do orçamento ","")&IF(SUMPRODUCT((tbParcelas[1ª fatura]<=$M$3)*(tbParcelas[Última fatura]>=$M$3)*(COUNTIFS(tbLancamentos[Mês],$M$3,tbLancamentos[Descrição],tbParcelas[Descrição])=0))>0,SUMPRODUCT((tbParcelas[1ª fatura]<=$M$3)*(tbParcelas[Última fatura]>=$M$3)*(COUNTIFS(tbLancamentos[Mês],$M$3,tbLancamentos[Descrição],tbParcelas[Descrição])=0))&" parcela(s) do cartão para lançar ","")&IF($K$7<0,"saldo do mês negativo","")) -> ⚠ 1 conta(s) vencida(s) 2 categoria(s) acima do orçamento 4 parcela(s) do cartão para lançar | J3: =SUM(tbPatrimonio[Valor atual])-SUM(tbDividas[Saldo devedor]) -> 5312.6995 | M3: 46296
B6: ● RECEITAS | E6: ● DESPESAS | H6: ● INVESTIDO | K6: ● SALDO DO MÊS | N6: ● TAXA DE POUPANÇA
B7: =SUMIFS(tbLancamentos[Valor],tbLancamentos[Mês],$M$3,tbLancamentos[Tipo],"Receita") -> 5800 | E7: =SUMIFS(tbLancamentos[Valor],tbLancamentos[Mês],$M$3,tbLancamentos[Tipo],"Despesa") -> 4095 | H7: =SUMIFS(tbLancamentos[Valor],tbLancamentos[Mês],$M$3,tbLancamentos[Tipo],"Investimento") -> 851.49 | K7: =B7-E7-H7 -> 853.51 | N7: =IF(B7=0,0,(B7-E7)/B7) -> 0.29396552
B8: =IFERROR(B7/SUMIFS(tbLancamentos[Valor],tbLancamentos[Mês],EDATE($M$3,-1),tbLancamentos[Tipo],"Receita")-1,"") -> 0 | E8: =IFERROR(E7/SUMIFS(tbLancamentos[Valor],tbLancamentos[Mês],EDATE($M$3,-1),tbLancamentos[Tipo],"Despesa")-1,"") -> 0.094261474 | H8: =IFERROR(H7/SUMIFS(tbLancamentos[Valor],tbLancamentos[Mês],EDATE($M$3,-1),tbLancamentos[Tipo],"Investimento")-1,"") -> -0.16277629 | K8: =K7-(SUMIFS(tbLancamentos[Valor],tbLancamentos[Mês],EDATE($M$3,-1),tbLancamentos[Tipo],"Receita")-SUMIFS(tbLancamentos[Valor],tbLancamentos[Mês],EDATE($M$3,-1),tbLancamentos[Tipo],"Despesa")-SUMIFS(tbLancamentos[Valor],tbLancamentos[Mês],EDATE($M$3,-1),tbLancamentos[Tipo],"Investimento")) -> -187.2 | N8: =IF(B7=0,"",IF(N7>=0.2,"✓ acima da meta de 20%","meta: guardar 20% da renda")) -> ✓ acima da meta de 20%
B27: Orçado x gasto no mês
B28: Categoria | D28: Orçado | E28: Gasto | F28: Diferença | G28: % usado
B29: =IFERROR(INDEX(tbCategorias[Categoria],MATCH(ROWS(B$29:B29),tbCategorias[Ordem],0)),"") -> Moradia | D29: =IF($B29="","",N(INDEX(tbCategorias[Orçamento mensal],MATCH($B29,tbCategorias[Categoria],0)))) -> 1200 | E29: =IF($B29="","",SUMIFS(tbLancamentos[Valor],tbLancamentos[Mês],$M$3,tbLancamentos[Categoria],$B29)) -> 1200 | F29: =IF($B29="","",D29-E29) -> 0 | G29: =IF(OR($B29="",N(D29)=0),"",E29/D29) -> 1
B30: =IFERROR(INDEX(tbCategorias[Categoria],MATCH(ROWS(B$29:B30),tbCategorias[Ordem],0)),"") -> Contas da casa | D30: =IF($B30="","",N(INDEX(tbCategorias[Orçamento mensal],MATCH($B30,tbCategorias[Categoria],0)))) -> 420 | E30: =IF($B30="","",SUMIFS(tbLancamentos[Valor],tbLancamentos[Mês],$M$3,tbLancamentos[Categoria],$B30)) -> 395.05 | F30: =IF($B30="","",D30-E30) -> 24.95 | G30: =IF(OR($B30="",N(D30)=0),"",E30/D30) -> 0.94059524
B31: =IFERROR(INDEX(tbCategorias[Categoria],MATCH(ROWS(B$29:B31),tbCategorias[Ordem],0)),"") -> Mercado | D31: =IF($B31="","",N(INDEX(tbCategorias[Orçamento mensal],MATCH($B31,tbCategorias[Categoria],0)))) -> 950 | E31: =IF($B31="","",SUMIFS(tbLancamentos[Valor],tbLancamentos[Mês],$M$3,tbLancamentos[Categoria],$B31)) -> 908.6 | F31: =IF($B31="","",D31-E31) -> 41.4 | G31: =IF(OR($B31="",N(D31)=0),"",E31/D31) -> 0.95642105
B32: =IFERROR(INDEX(tbCategorias[Categoria],MATCH(ROWS(B$29:B32),tbCategorias[Ordem],0)),"") -> Transporte | D32: =IF($B32="","",N(INDEX(tbCategorias[Orçamento mensal],MATCH($B32,tbCategorias[Categoria],0)))) -> 380 | E32: =IF($B32="","",SUMIFS(tbLancamentos[Valor],tbLancamentos[Mês],$M$3,tbLancamentos[Categoria],$B32)) -> 314.62 | F32: =IF($B32="","",D32-E32) -> 65.38 | G32: =IF(OR($B32="",N(D32)=0),"",E32/D32) -> 0.82794737
B33: =IFERROR(INDEX(tbCategorias[Categoria],MATCH(ROWS(B$29:B33),tbCategorias[Ordem],0)),"") -> Saúde | D33: =IF($B33="","",N(INDEX(tbCategorias[Orçamento mensal],MATCH($B33,tbCategorias[Categoria],0)))) -> 350 | E33: =IF($B33="","",SUMIFS(tbLancamentos[Valor],tbLancamentos[Mês],$M$3,tbLancamentos[Categoria],$B33)) -> 209.23 | F33: =IF($B33="","",D33-E33) -> 140.77 | G33: =IF(OR($B33="",N(D33)=0),"",E33/D33) -> 0.5978
B34: =IFERROR(INDEX(tbCategorias[Categoria],MATCH(ROWS(B$29:B34),tbCategorias[Ordem],0)),"") -> Educação | D34: =IF($B34="","",N(INDEX(tbCategorias[Orçamento mensal],MATCH($B34,tbCategorias[Categoria],0)))) -> 150 | E34: =IF($B34="","",SUMIFS(tbLancamentos[Valor],tbLancamentos[Mês],$M$3,tbLancamentos[Categoria],$B34)) -> 79.9 | F34: =IF($B34="","",D34-E34) -> 70.1 | G34: =IF(OR($B34="",N(D34)=0),"",E34/D34) -> 0.53266667
B35: =IFERROR(INDEX(tbCategorias[Categoria],MATCH(ROWS(B$29:B35),tbCategorias[Ordem],0)),"") -> Restaurantes e delivery | D35: =IF($B35="","",N(INDEX(tbCategorias[Orçamento mensal],MATCH($B35,tbCategorias[Categoria],0)))) -> 350 | E35: =IF($B35="","",SUMIFS(tbLancamentos[Valor],tbLancamentos[Mês],$M$3,tbLancamentos[Categoria],$B35)) -> 206.14 | F35: =IF($B35="","",D35-E35) -> 143.86 | G35: =IF(OR($B35="",N(D35)=0),"",E35/D35) -> 0.58897143
B36: =IFERROR(INDEX(tbCategorias[Categoria],MATCH(ROWS(B$29:B36),tbCategorias[Ordem],0)),"") -> Lazer | D36: =IF($B36="","",N(INDEX(tbCategorias[Orçamento mensal],MATCH($B36,tbCategorias[Categoria],0)))) -> 250 | E36: =IF($B36="","",SUMIFS(tbLancamentos[Valor],tbLancamentos[Mês],$M$3,tbLancamentos[Categoria],$B36)) -> 178.11 | F36: =IF($B36="","",D36-E36) -> 71.89 | G36: =IF(OR($B36="",N(D36)=0),"",E36/D36) -> 0.71244
B37: =IFERROR(INDEX(tbCategorias[Categoria],MATCH(ROWS(B$29:B37),tbCategorias[Ordem],0)),"") -> Assinaturas | D37: =IF($B37="","",N(INDEX(tbCategorias[Orçamento mensal],MATCH($B37,tbCategorias[Categoria],0)))) -> 90 | E37: =IF($B37="","",SUMIFS(tbLancamentos[Valor],tbLancamentos[Mês],$M$3,tbLancamentos[Categoria],$B37)) -> 66.8 | F37: =IF($B37="","",D37-E37) -> 23.2 | G37: =IF(OR($B37="",N(D37)=0),"",E37/D37) -> 0.74222222
B38: =IFERROR(INDEX(tbCategorias[Categoria],MATCH(ROWS(B$29:B38),tbCategorias[Ordem],0)),"") -> Compras | D38: =IF($B38="","",N(INDEX(tbCategorias[Orçamento mensal],MATCH($B38,tbCategorias[Categoria],0)))) -> 300 | E38: =IF($B38="","",SUMIFS(tbLancamentos[Valor],tbLancamentos[Mês],$M$3,tbLancamentos[Categoria],$B38)) -> 406.92 | F38: =IF($B38="","",D38-E38) -> -106.92 | G38: =IF(OR($B38="",N(D38)=0),"",E38/D38) -> 1.3564
B39: =IFERROR(INDEX(tbCategorias[Categoria],MATCH(ROWS(B$29:B39),tbCategorias[Ordem],0)),"") -> Outros | D39: =IF($B39="","",N(INDEX(tbCategorias[Orçamento mensal],MATCH($B39,tbCategorias[Categoria],0)))) -> 100 | E39: =IF($B39="","",SUMIFS(tbLancamentos[Valor],tbLancamentos[Mês],$M$3,tbLancamentos[Categoria],$B39)) -> 129.63 | F39: =IF($B39="","",D39-E39) -> -29.63 | G39: =IF(OR($B39="",N(D39)=0),"",E39/D39) -> 1.2963
B40: =IFERROR(INDEX(tbCategorias[Categoria],MATCH(ROWS(B$29:B40),tbCategorias[Ordem],0)),"") -> Investimentos | D40: =IF($B40="","",N(INDEX(tbCategorias[Orçamento mensal],MATCH($B40,tbCategorias[Categoria],0)))) -> 800 | E40: =IF($B40="","",SUMIFS(tbLancamentos[Valor],tbLancamentos[Mês],$M$3,tbLancamentos[Categoria],$B40)) -> 851.49 | F40: =IF($B40="","",D40-E40) -> -51.49 | G40: =IF(OR($B40="",N(D40)=0),"",E40/D40) -> 1.0643625
... B43: =IFERROR(INDEX(tbCategorias[Categoria],MATCH(ROWS(B$29:B43),tbCategorias[Ordem],0)),"") | D43: =IF($B43="","",N(INDEX(tbCategorias[Orçamento mensal],MATCH($B43,tbCategorias[Categoria],0)))) | E43: =IF($B43="","",SUMIFS(tbLancamentos[Valor],tbLancamentos[Mês],$M$3,tbLancamentos[Categoria],$B43)) | F43: =IF($B43="","",D43-E43) | G43: =IF(OR($B43="",N(D43)=0),"",E43/D43)
B44: Total | D44: =SUM(D29:D43) -> 5340 | E44: =SUM(E29:E43) -> 4946.49 | F44: =D44-E44 -> 393.51 | G44: =IF(D44=0,"",E44/D44) -> 0.92630899
B45: Em coral: passou do orçamento. Em Investimentos, aplicar mais que o planejado aparece em verde.
B64: Divisão da renda (regra 50/30/20) | J64: Metas
B65: Grupo | D65: Valor | E65: % da renda | F65: Referência | G65: Situação | J65: Meta | M65: Alvo | N65: Guardado | O65: Progresso
B66: Essencial | D66: =SUMIFS(tbLancamentos[Valor],tbLancamentos[Mês],$M$3,tbLancamentos[Grupo],$B66) -> 3107.4 | E66: =IF($B$7=0,"",D66/$B$7) -> 0.53575862 | F66: 0.5 | G66: =IF(E66="","",IF($B66="Investimento",IF(E66>=F66,"✓ dentro","abaixo da referência"),IF(E66<=F66,"✓ dentro","acima da referência"))) -> acima da referência | J66: =IFERROR(INDEX(tbMetas[Meta],ROWS(J$66:J66)),"") -> Reserva de emergência | M66: =IF($J66="","",INDEX(tbMetas[Valor alvo],ROWS(M$66:M66))) -> 18000 | N66: =IF($J66="","",INDEX(tbMetas[Já guardado],ROWS(N$66:N66))) -> 7200 | O66: =IF(OR($J66="",N(M66)=0),"",N66/M66) -> 0.4
B67: Estilo de vida | D67: =SUMIFS(tbLancamentos[Valor],tbLancamentos[Mês],$M$3,tbLancamentos[Grupo],$B67) -> 987.6 | E67: =IF($B$7=0,"",D67/$B$7) -> 0.17027586 | F67: 0.3 | G67: =IF(E67="","",IF($B67="Investimento",IF(E67>=F67,"✓ dentro","abaixo da referência"),IF(E67<=F67,"✓ dentro","acima da referência"))) -> ✓ dentro | J67: =IFERROR(INDEX(tbMetas[Meta],ROWS(J$66:J67)),"") -> Viagem de férias | M67: =IF($J67="","",INDEX(tbMetas[Valor alvo],ROWS(M$66:M67))) -> 5000 | N67: =IF($J67="","",INDEX(tbMetas[Já guardado],ROWS(N$66:N67))) -> 1800 | O67: =IF(OR($J67="",N(M67)=0),"",N67/M67) -> 0.36
B68: Investimento | D68: =SUMIFS(tbLancamentos[Valor],tbLancamentos[Mês],$M$3,tbLancamentos[Grupo],$B68) -> 851.49 | E68: =IF($B$7=0,"",D68/$B$7) -> 0.14680862 | F68: 0.2 | G68: =IF(E68="","",IF($B68="Investimento",IF(E68>=F68,"✓ dentro","abaixo da referência"),IF(E68<=F68,"✓ dentro","acima da referência"))) -> abaixo da referência | J68: =IFERROR(INDEX(tbMetas[Meta],ROWS(J$66:J68)),"") -> Notebook novo | M68: =IF($J68="","",INDEX(tbMetas[Valor alvo],ROWS(M$66:M68))) -> 4500 | N68: =IF($J68="","",INDEX(tbMetas[Já guardado],ROWS(N$66:N68))) -> 1200 | O68: =IF(OR($J68="",N(M68)=0),"",N68/M68) -> 0.26666667
B69: Sobrou no mês | D69: =K7 -> 853.51 | E69: =IF($B$7=0,"",D69/$B$7) -> 0.1471569 | J69: =IFERROR(INDEX(tbMetas[Meta],ROWS(J$66:J69)),"") -> Entrada do apartamento | M69: =IF($J69="","",INDEX(tbMetas[Valor alvo],ROWS(M$66:M69))) -> 40000 | N69: =IF($J69="","",INDEX(tbMetas[Já guardado],ROWS(N$66:N69))) -> 3000 | O69: =IF(OR($J69="",N(M69)=0),"",N69/M69) -> 0.075
J70: =IFERROR(INDEX(tbMetas[Meta],ROWS(J$66:J70)),"") | M70: =IF($J70="","",INDEX(tbMetas[Valor alvo],ROWS(M$66:M70))) | N70: =IF($J70="","",INDEX(tbMetas[Já guardado],ROWS(N$66:N70))) | O70: =IF(OR($J70="",N(M70)=0),"",N70/M70)
B73: Visão do ano (de janeiro até o mês escolhido)
B74: ● RECEBIDO NO ANO | E74: ● GASTO NO ANO | H74: ● INVESTIDO NO ANO | K74: ● SALDO NO ANO | N74: ● RESERVA DE EMERGÊNCIA
B75: =SUMIFS(tbLancamentos[Valor],tbLancamentos[Tipo],"Receita",tbLancamentos[Mês],">="&DATE(YEAR($M$3),1,1),tbLancamentos[Mês],"<="&$M$3) -> 61156.69 | E75: =SUMIFS(tbLancamentos[Valor],tbLancamentos[Tipo],"Despesa",tbLancamentos[Mês],">="&DATE(YEAR($M$3),1,1),tbLancamentos[Mês],"<="&$M$3) -> 39958.02 | H75: =SUMIFS(tbLancamentos[Valor],tbLancamentos[Tipo],"Investimento",tbLancamentos[Mês],">="&DATE(YEAR($M$3),1,1),tbLancamentos[Mês],"<="&$M$3) -> 7254.68 | K75: =B75-E75-H75 -> 13943.99 | N75: =IFERROR(INDEX(tbMetas[Já guardado],MATCH("Reserva*",tbMetas[Meta],0))/(E75/MONTH($M$3)),"") -> 1.8018911
B76: =B75/MONTH($M$3) -> 6115.669 | E76: =E75/MONTH($M$3) -> 3995.802 | H76: =H75/MONTH($M$3) -> 725.468 | K76: =IF(B75=0,"",(B75-E75)/B75) -> 0.3466288 | N76: ="dos seus gastos cobertos (ideal: 6)" -> dos seus gastos cobertos (ideal: 6)
B79: Maiores gastos do mês | J79: Ritmo do mês
B80: Data | C80: Descrição | F80: Categoria | H80: Valor | J80: Se o ritmo de gastos continuar igual até o fim do mês:
B81: =IF(Calc!$I3="","",INDEX(tbLancamentos[Data],Calc!$I3)) -> 46305 | C81: =IF(Calc!$I3="","",INDEX(tbLancamentos[Descrição],Calc!$I3)) -> Aluguel | F81: =IF(Calc!$I3="","",INDEX(tbLancamentos[Categoria],Calc!$I3)) -> Moradia | H81: =IF(Calc!$I3="","",INDEX(tbLancamentos[Valor],Calc!$I3)) -> 1200 | J81: Dias do mês considerados | O81: =IF(AND(YEAR(TODAY())=YEAR($M$3),MONTH(TODAY())=MONTH($M$3)),DAY(TODAY()),DAY(EOMONTH($M$3,0))) -> 26
B82: =IF(Calc!$I4="","",INDEX(tbLancamentos[Data],Calc!$I4)) -> 46308 | C82: =IF(Calc!$I4="","",INDEX(tbLancamentos[Descrição],Calc!$I4)) -> Livros | F82: =IF(Calc!$I4="","",INDEX(tbLancamentos[Categoria],Calc!$I4)) -> Compras | H82: =IF(Calc!$I4="","",INDEX(tbLancamentos[Valor],Calc!$I4)) -> 406.92 | J82: Gasto médio por dia | O82: =IF(N(O81)=0,0,E7/O81) -> 157.5
B83: =IF(Calc!$I5="","",INDEX(tbLancamentos[Data],Calc!$I5)) -> 46299 | C83: =IF(Calc!$I5="","",INDEX(tbLancamentos[Descrição],Calc!$I5)) -> Supermercado | F83: =IF(Calc!$I5="","",INDEX(tbLancamentos[Categoria],Calc!$I5)) -> Mercado | H83: =IF(Calc!$I5="","",INDEX(tbLancamentos[Valor],Calc!$I5)) -> 318.36 | J83: Projeção de gasto no mês | O83: =O82*DAY(EOMONTH($M$3,0)) -> 4882.5
B84: =IF(Calc!$I6="","",INDEX(tbLancamentos[Data],Calc!$I6)) -> 46306 | C84: =IF(Calc!$I6="","",INDEX(tbLancamentos[Descrição],Calc!$I6)) -> Supermercado | F84: =IF(Calc!$I6="","",INDEX(tbLancamentos[Categoria],Calc!$I6)) -> Mercado | H84: =IF(Calc!$I6="","",INDEX(tbLancamentos[Valor],Calc!$I6)) -> 308.9 | J84: Orçamento de despesas | O84: =SUMIFS(tbCategorias[Orçamento mensal],tbCategorias[Tipo],"Despesa") -> 4540
B85: =IF(Calc!$I7="","",INDEX(tbLancamentos[Data],Calc!$I7)) -> 46307 | C85: =IF(Calc!$I7="","",INDEX(tbLancamentos[Descrição],Calc!$I7)) -> Conta de luz | F85: =IF(Calc!$I7="","",INDEX(tbLancamentos[Categoria],Calc!$I7)) -> Contas da casa | H85: =IF(Calc!$I7="","",INDEX(tbLancamentos[Valor],Calc!$I7)) -> 165.63 | J85: Projeção x orçamento | O85: =IF(N(O84)=0,"",O83/O84) -> 1.0754405
...

Sheet Celular
B1: Minhas finanças
B2: =IF(SUMPRODUCT((SUMIFS(tbLancamentos[Valor],tbLancamentos[Mês],$C$6,tbLancamentos[Descrição],tbContas[Conta])=0)*(DATE(YEAR($C$6),MONTH($C$6),tbContas[Dia do vencimento])<TODAY()))+SUMPRODUCT((tbCategorias[Tipo]="Despesa")*(SUMIFS(tbLancamentos[Valor],tbLancamentos[Mês],$C$6,tbLancamentos[Categoria],tbCategorias[Categoria])>tbCategorias[Orçamento mensal]))+SUMPRODUCT((tbParcelas[1ª fatura]<=$C$6)*(tbParcelas[Última fatura]>=$C$6)*(COUNTIFS(tbLancamentos[Mês],$C$6,tbLancamentos[Descrição],tbParcelas[Descrição])=0))+($C$12<0)=0,"✓ Tudo em dia neste mês","⚠ "&IF(SUMPRODUCT((SUMIFS(tbLancamentos[Valor],tbLancamentos[Mês],$C$6,tbLancamentos[Descrição],tbContas[Conta])=0)*(DATE(YEAR($C$6),MONTH($C$6),tbContas[Dia do vencimento])<TODAY()))>0,SUMPRODUCT((SUMIFS(tbLancamentos[Valor],tbLancamentos[Mês],$C$6,tbLancamentos[Descrição],tbContas[Conta])=0)*(DATE(YEAR($C$6),MONTH($C$6),tbContas[Dia do vencimento])<TODAY()))&" conta(s) vencida(s) ","")&IF(SUMPRODUCT((tbCategorias[Tipo]="Despesa")*(SUMIFS(tbLancamentos[Valor],tbLancamentos[Mês],$C$6,tbLancamentos[Categoria],tbCategorias[Categoria])>tbCategorias[Orçamento mensal]))>0,SUMPRODUCT((tbCategorias[Tipo]="Despesa")*(SUMIFS(tbLancamentos[Valor],tbLancamentos[Mês],$C$6,tbLancamentos[Categoria],tbCategorias[Categoria])>tbCategorias[Orçamento mensal]))&" categoria(s) acima do orçamento ","")&IF(SUMPRODUCT((tbParcelas[1ª fatura]<=$C$6)*(tbParcelas[Última fatura]>=$C$6)*(COUNTIFS(tbLancamentos[Mês],$C$6,tbLancamentos[Descrição],tbParcelas[Descrição])=0))>0,SUMPRODUCT((tbParcelas[1ª fatura]<=$C$6)*(tbParcelas[Última fatura]>=$C$6)*(COUNTIFS(tbLancamentos[Mês],$C$6,tbLancamentos[Descrição],tbParcelas[Descrição])=0))&" parcela(s) do cartão para lançar ","")&IF($C$12<0,"saldo do mês negativo","")) -> ⚠ 1 conta(s) vencida(s) 2 categoria(s) acima do orçamento 4 parcela(s) do cartão para lançar
B3: =HYPERLINK("#'Painel'!A1","Painel completo ›") -> Painel completo › | C3: =HYPERLINK("#'Lançamentos'!A1","Lançar gasto ›") -> Lançar gasto ›
B4: =HYPERLINK("#'Contas fixas'!A1","Contas fixas ›") -> Contas fixas › | C4: =HYPERLINK("#'Metas'!A1","Metas ›") -> Metas ›
B6: Mês | C6: 46296
B8: Resumo do mês
B9: Receitas | C9: =SUMIFS(tbLancamentos[Valor],tbLancamentos[Mês],$C$6,tbLancamentos[Tipo],"Receita") -> 5800
B10: Despesas | C10: =SUMIFS(tbLancamentos[Valor],tbLancamentos[Mês],$C$6,tbLancamentos[Tipo],"Despesa") -> 4095
B11: Investido | C11: =SUMIFS(tbLancamentos[Valor],tbLancamentos[Mês],$C$6,tbLancamentos[Tipo],"Investimento") -> 851.49
B12: Saldo do mês | C12: =C9-C10-C11 -> 853.51
B13: Taxa de poupança | C13: =IF(C9=0,0,(C9-C10)/C9) -> 0.29396552
B14: Despesas vs mês anterior | C14: =IFERROR(C10/SUMIFS(tbLancamentos[Valor],tbLancamentos[Mês],EDATE($C$6,-1),tbLancamentos[Tipo],"Despesa")-1,"") -> 0.094261474
B16: Orçamento do mês
B17: Orçamento de despesas | C17: =SUMIFS(tbCategorias[Orçamento mensal],tbCategorias[Tipo],"Despesa") -> 4540
B18: % do orçamento usado | C18: =IF(C17=0,"",C10/C17) -> 0.90198238
B19: Projeção até o fim do mês | C19: =IF(AND(YEAR(TODAY())=YEAR($C$6),MONTH(TODAY())=MONTH($C$6)),C10/DAY(TODAY())*DAY(EOMONTH($C$6,0)),C10) -> 4882.5
B20: Projeção x orçamento | C20: =IF(C17=0,"",C19/C17) -> 1.0754405
B22: Onde mais gastou
B23: =Calc!N3 -> Moradia | C23: =IF(Calc!M3="","",ROUND(Calc!M3,2)) -> 1200
B24: =Calc!N4 -> Mercado | C24: =IF(Calc!M4="","",ROUND(Calc!M4,2)) -> 908.6
B25: =Calc!N5 -> Compras | C25: =IF(Calc!M5="","",ROUND(Calc!M5,2)) -> 406.92
B26: =Calc!N6 -> Contas da casa | C26: =IF(Calc!M6="","",ROUND(Calc!M6,2)) -> 395.05
B27: =Calc!N7 -> Transporte | C27: =IF(Calc!M7="","",ROUND(Calc!M7,2)) -> 314.62
B29: Contas fixas
B30: Contas pagas | C30: =SUMPRODUCT(--(SUMIFS(tbLancamentos[Valor],tbLancamentos[Mês],$C$6,tbLancamentos[Descrição],tbContas[Conta])>0))&" de "&ROWS(tbContas[]) -> 10 de 12
B31: Falta pagar | C31: =SUMPRODUCT(tbContas[Valor previsto]*(SUMIFS(tbLancamentos[Valor],tbLancamentos[Mês],$C$6,tbLancamentos[Descrição],tbContas[Conta])=0)) -> 75
B32: Contas vencidas | C32: =SUMPRODUCT((SUMIFS(tbLancamentos[Valor],tbLancamentos[Mês],$C$6,tbLancamentos[Descrição],tbContas[Conta])=0)*(DATE(YEAR($C$6),MONTH($C$6),tbContas[Dia do vencimento])<TODAY())) -> 1
B34: Metas
B35: =IFERROR(INDEX(tbMetas[Meta],1),"") -> Reserva de emergência | C35: =IF(B35="","",INDEX(tbMetas[Progresso],1)) -> 0.4
B36: =IFERROR(INDEX(tbMetas[Meta],2),"") -> Viagem de férias | C36: =IF(B36="","",INDEX(tbMetas[Progresso],2)) -> 0.36
B37: =IFERROR(INDEX(tbMetas[Meta],3),"") -> Notebook novo | C37: =IF(B37="","",INDEX(tbMetas[Progresso],3)) -> 0.26666667
B38: =IFERROR(INDEX(tbMetas[Meta],4),"") -> Entrada do apartamento | C38: =IF(B38="","",INDEX(tbMetas[Progresso],4)) -> 0.075
B40: Patrimônio
B41: Patrimônio total | C41: =SUM(tbPatrimonio[Valor atual]) -> 17357.9
B42: Rendimento | C42: =SUM(tbPatrimonio[Rendimento]) -> 757.9
B43: Dívidas (saldo devedor) | C43: =SUM(tbDividas[Saldo devedor]) -> 12045.201
B44: Patrimônio líquido | C44: =C41-C43 -> 5312.6995
B46: Cartão de crédito
B47: Parcelas na fatura do mês | C47: =SUMPRODUCT(tbParcelas[Valor da parcela]*(tbParcelas[1ª fatura]<=$C$6)*(tbParcelas[Última fatura]>=$C$6)) -> 920
B48: Parcelas dos próximos meses | C48: =IFERROR(SUMPRODUCT(tbParcelas[Valor da parcela]*(((((YEAR(tbParcelas[Última fatura])-YEAR($C$6))*12+MONTH(tbParcelas[Última fatura])-MONTH($C$6))>0)*((YEAR(tbParcelas[Última fatura])-YEAR($C$6))*12+MONTH(tbParcelas[Última fatura])-MONTH($C$6)))-(((((YEAR(tbParcelas[Última fatura])-YEAR($C$6))*12+MONTH(tbParcelas[Última fatura])-MONTH($C$6))>0)*((YEAR(tbParcelas[Última fatura])-YEAR($C$6))*12+MONTH(tbParcelas[Última fatura])-MONTH($C$6)))>tbParcelas[Parcelas])*(((((YEAR(tbParcelas[Última fatura])-YEAR($C$6))*12+MONTH(tbParcelas[Última fatura])-MONTH($C$6))>0)*((YEAR(tbParcelas[Última fatura])-YEAR($C$6))*12+MONTH(tbParcelas[Última fatura])-MONTH($C$6)))-tbParcelas[Parcelas]))),0) -> 5800
...

Sheet Lançamentos
B1: Lançamentos
B2: Uma linha por entrada ou saída. Valor sempre positivo: o tipo da categoria define se é receita, despesa ou investimento.
B3: =HYPERLINK("#'Painel'!A1","Painel") -> Painel | C3: =HYPERLINK("#'Celular'!A1","Celular") -> Celular | D3: Lançamentos | E3: =HYPERLINK("#'Contas fixas'!A1","Contas") -> Contas | F3: =HYPERLINK("#'Cartão'!A1","Cartão") -> Cartão | G3: =HYPERLINK("#'Dívidas'!A1","Dívidas") -> Dívidas | H3: =HYPERLINK("#'Categorias'!A1","Categorias") -> Categorias | I3: =HYPERLINK("#'Metas'!A1","Metas") -> Metas | J3: =HYPERLINK("#'Patrimônio'!A1","Patrimônio") -> Patrimônio | K3: =HYPERLINK("#'Simulador'!A1","Simulador") -> Simulador | L3: =HYPERLINK("#'Resumo'!A1","Resumo") -> Resumo | M3: =HYPERLINK("#'Como usar'!A1","Ajuda") -> Ajuda
B5: Data | C5: Descrição | D5: Categoria | E5: Valor | F5: Pagamento | G5: Tipo | H5: Grupo | I5: Mês | K5: Como preencher
B6: 46026 | C6: Supermercado | D6: Mercado | E6: 277.48 | F6: Cartão de crédito | G6: =IFERROR(INDEX(tbCategorias[Tipo],MATCH(tbLancamentos[[#This Row],[Categoria]],tbCategorias[Categoria],0)),"Categoria?") -> Despesa | H6: =IFERROR(INDEX(tbCategorias[Grupo],MATCH(tbLancamentos[[#This Row],[Categoria]],tbCategorias[Categoria],0)),"") -> Essencial | I6: =IF(tbLancamentos[[#This Row],[Data]]="","",DATE(YEAR(tbLancamentos[[#This Row],[Data]]),MONTH(tbLancamentos[[#This Row],[Data]]),1)) -> 46023 | K6: Escreva logo abaixo da última linha: a tabela cresce sozinha.
B7: 46026 | C7: Cashback do cartão | D7: Outras receitas | E7: 83.79 | F7: Pix | G7: =IFERROR(INDEX(tbCategorias[Tipo],MATCH(tbLancamentos[[#This Row],[Categoria]],tbCategorias[Categoria],0)),"Categoria?") -> Receita | H7: =IFERROR(INDEX(tbCategorias[Grupo],MATCH(tbLancamentos[[#This Row],[Categoria]],tbCategorias[Categoria],0)),"") -> Renda | I7: =IF(tbLancamentos[[#This Row],[Data]]="","",DATE(YEAR(tbLancamentos[[#This Row],[Data]]),MONTH(tbLancamentos[[#This Row],[Data]]),1)) -> 46023 | K7: Colunas sem cor: você preenche. Colunas cinza-azuladas: calculadas.
B8: 46026 | C8: iFood | D8: Restaurantes e delivery | E8: 32.69 | F8: Pix | G8: =IFERROR(INDEX(tbCategorias[Tipo],MATCH(tbLancamentos[[#This Row],[Categoria]],tbCategorias[Categoria],0)),"Categoria?") -> Despesa | H8: =IFERROR(INDEX(tbCategorias[Grupo],MATCH(tbLancamentos[[#This Row],[Categoria]],tbCategorias[Categoria],0)),"") -> Estilo de vida | I8: =IF(tbLancamentos[[#This Row],[Data]]="","",DATE(YEAR(tbLancamentos[[#This Row],[Data]]),MONTH(tbLancamentos[[#This Row],[Data]]),1)) -> 46023 | K8: Os lançamentos que vêm aqui são fictícios: apague as linhas e use os seus.
B9: 46027 | C9: Salário | D9: Salário | E9: 5800 | F9: Pix | G9: =IFERROR(INDEX(tbCategorias[Tipo],MATCH(tbLancamentos[[#This Row],[Categoria]],tbCategorias[Categoria],0)),"Categoria?") -> Receita | H9: =IFERROR(INDEX(tbCategorias[Grupo],MATCH(tbLancamentos[[#This Row],[Categoria]],tbCategorias[Categoria],0)),"") -> Renda | I9: =IF(tbLancamentos[[#This Row],[Data]]="","",DATE(YEAR(tbLancamentos[[#This Row],[Data]]),MONTH(tbLancamentos[[#This Row],[Data]]),1)) -> 46023
B10: 46028 | C10: Combustível | D10: Transporte | E10: 136.41 | F10: Cartão de crédito | G10: =IFERROR(INDEX(tbCategorias[Tipo],MATCH(tbLancamentos[[#This Row],[Categoria]],tbCategorias[Categoria],0)),"Categoria?") -> Despesa | H10: =IFERROR(INDEX(tbCategorias[Grupo],MATCH(tbLancamentos[[#This Row],[Categoria]],tbCategorias[Categoria],0)),"") -> Essencial | I10: =IF(tbLancamentos[[#This Row],[Data]]="","",DATE(YEAR(tbLancamentos[[#This Row],[Data]]),MONTH(tbLancamentos[[#This Row],[Data]]),1)) -> 46023
B11: 46029 | C11: Aporte reserva de emergência | D11: Investimentos | E11: 600 | F11: Pix | G11: =IFERROR(INDEX(tbCategorias[Tipo],MATCH(tbLancamentos[[#This Row],[Categoria]],tbCategorias[Categoria],0)),"Categoria?") -> Investimento | H11: =IFERROR(INDEX(tbCategorias[Grupo],MATCH(tbLancamentos[[#This Row],[Categoria]],tbCategorias[Categoria],0)),"") -> Investimento | I11: =IF(tbLancamentos[[#This Row],[Data]]="","",DATE(YEAR(tbLancamentos[[#This Row],[Data]]),MONTH(tbLancamentos[[#This Row],[Data]]),1)) -> 46023
B12: 46030 | C12: Passeio | D12: Lazer | E12: 60.11 | F12: Cartão de crédito | G12: =IFERROR(INDEX(tbCategorias[Tipo],MATCH(tbLancamentos[[#This Row],[Categoria]],tbCategorias[Categoria],0)),"Categoria?") -> Despesa | H12: =IFERROR(INDEX(tbCategorias[Grupo],MATCH(tbLancamentos[[#This Row],[Categoria]],tbCategorias[Categoria],0)),"") -> Estilo de vida | I12: =IF(tbLancamentos[[#This Row],[Data]]="","",DATE(YEAR(tbLancamentos[[#This Row],[Data]]),MONTH(tbLancamentos[[#This Row],[Data]]),1)) -> 46023
B13: 46030 | C13: Academia | D13: Saúde | E13: 99.9 | F13: Cartão de crédito | G13: =IFERROR(INDEX(tbCategorias[Tipo],MATCH(tbLancamentos[[#This Row],[Categoria]],tbCategorias[Categoria],0)),"Categoria?") -> Despesa | H13: =IFERROR(INDEX(tbCategorias[Grupo],MATCH(tbLancamentos[[#This Row],[Categoria]],tbCategorias[Categoria],0)),"") -> Essencial | I13: =IF(tbLancamentos[[#This Row],[Data]]="","",DATE(YEAR(tbLancamentos[[#This Row],[Data]]),MONTH(tbLancamentos[[#This Row],[Data]]),1)) -> 46023
B14: 46030 | C14: Lanchonete | D14: Restaurantes e delivery | E14: 103.54 | F14: Cartão de crédito | G14: =IFERROR(INDEX(tbCategorias[Tipo],MATCH(tbLancamentos[[#This Row],[Categoria]],tbCategorias[Categoria],0)),"Categoria?") -> Despesa | H14: =IFERROR(INDEX(tbCategorias[Grupo],MATCH(tbLancamentos[[#This Row],[Categoria]],tbCategorias[Categoria],0)),"") -> Estilo de vida | I14: =IF(tbLancamentos[[#This Row],[Data]]="","",DATE(YEAR(tbLancamentos[[#This Row],[Data]]),MONTH(tbLancamentos[[#This Row],[Data]]),1)) -> 46023
B15: 46030 | C15: Plano odontológico | D15: Saúde | E15: 59.9 | F15: Boleto | G15: =IFERROR(INDEX(tbCategorias[Tipo],MATCH(tbLancamentos[[#This Row],[Categoria]],tbCategorias[Categoria],0)),"Categoria?") -> Despesa | H15: =IFERROR(INDEX(tbCategorias[Grupo],MATCH(tbLancamentos[[#This Row],[Categoria]],tbCategorias[Categoria],0)),"") -> Essencial | I15: =IF(tbLancamentos[[#This Row],[Data]]="","",DATE(YEAR(tbLancamentos[[#This Row],[Data]]),MONTH(tbLancamentos[[#This Row],[Data]]),1)) -> 46023
B16: 46032 | C16: Aluguel | D16: Moradia | E16: 1200 | F16: Boleto | G16: =IFERROR(INDEX(tbCategorias[Tipo],MATCH(tbLancamentos[[#This Row],[Categoria]],tbCategorias[Categoria],0)),"Categoria?") -> Despesa | H16: =IFERROR(INDEX(tbCategorias[Grupo],MATCH(tbLancamentos[[#This Row],[Categoria]],tbCategorias[Categoria],0)),"") -> Essencial | I16: =IF(tbLancamentos[[#This Row],[Data]]="","",DATE(YEAR(tbLancamentos[[#This Row],[Data]]),MONTH(tbLancamentos[[#This Row],[Data]]),1)) -> 46023
B17: 46032 | C17: Feira | D17: Mercado | E17: 180.45 | F17: Débito | G17: =IFERROR(INDEX(tbCategorias[Tipo],MATCH(tbLancamentos[[#This Row],[Categoria]],tbCategorias[Categoria],0)),"Categoria?") -> Despesa | H17: =IFERROR(INDEX(tbCategorias[Grupo],MATCH(tbLancamentos[[#This Row],[Categoria]],tbCategorias[Categoria],0)),"") -> Essencial | I17: =IF(tbLancamentos[[#This Row],[Data]]="","",DATE(YEAR(tbLancamentos[[#This Row],[Data]]),MONTH(tbLancamentos[[#This Row],[Data]]),1)) -> 46023
B18: 46034 | C18: Conta de luz | D18: Contas da casa | E18: 156.26 | F18: Boleto | G18: =IFERROR(INDEX(tbCategorias[Tipo],MATCH(tbLancamentos[[#This Row],[Categoria]],tbCategorias[Categoria],0)),"Categoria?") -> Despesa | H18: =IFERROR(INDEX(tbCategorias[Grupo],MATCH(tbLancamentos[[#This Row],[Categoria]],tbCategorias[Categoria],0)),"") -> Essencial | I18: =IF(tbLancamentos[[#This Row],[Data]]="","",DATE(YEAR(tbLancamentos[[#This Row],[Data]]),MONTH(tbLancamentos[[#This Row],[Data]]),1)) -> 46023
B19: 46035 | C19: Roupas | D19: Compras | E19: 211.33 | F19: Cartão de crédito | G19: =IFERROR(INDEX(tbCategorias[Tipo],MATCH(tbLancamentos[[#This Row],[Categoria]],tbCategorias[Categoria],0)),"Categoria?") -> Despesa | H19: =IFERROR(INDEX(tbCategorias[Grupo],MATCH(tbLancamentos[[#This Row],[Categoria]],tbCategorias[Categoria],0)),"") -> Estilo de vida | I19: =IF(tbLancamentos[[#This Row],[Data]]="","",DATE(YEAR(tbLancamentos[[#This Row],[Data]]),MONTH(tbLancamentos[[#This Row],[Data]]),1)) -> 46023
B20: 46036 | C20: Netflix | D20: Assinaturas | E20: 44.9 | F20: Cartão de crédito | G20: =IFERROR(INDEX(tbCategorias[Tipo],MATCH(tbLancamentos[[#This Row],[Categoria]],tbCategorias[Categoria],0)),"Categoria?") -> Despesa | H20: =IFERROR(INDEX(tbCategorias[Grupo],MATCH(tbLancamentos[[#This Row],[Categoria]],tbCategorias[Categoria],0)),"") -> Estilo de vida | I20: =IF(tbLancamentos[[#This Row],[Data]]="","",DATE(YEAR(tbLancamentos[[#This Row],[Data]]),MONTH(tbLancamentos[[#This Row],[Data]]),1)) -> 46023
... B299: 46320 | C299: Supermercado | D299: Mercado | E299: 120.41 | F299: Cartão de crédito | G299: =IFERROR(INDEX(tbCategorias[Tipo],MATCH(tbLancamentos[[#This Row],[Categoria]],tbCategorias[Categoria],0)),"Categoria?") -> Despesa | H299: =IFERROR(INDEX(tbCategorias[Grupo],MATCH(tbLancamentos[[#This Row],[Categoria]],tbCategorias[Categoria],0)),"") -> Essencial | I299: =IF(tbLancamentos[[#This Row],[Data]]="","",DATE(YEAR(tbLancamentos[[#This Row],[Data]]),MONTH(tbLancamentos[[#This Row],[Data]]),1)) -> 46296

Sheet Contas fixas
B1: Contas fixas
B2: Contas que se repetem todo mês. A situação confere se já existe um lançamento com a mesma descrição no mês escolhido.
B3: =HYPERLINK("#'Painel'!A1","Painel") -> Painel | C3: =HYPERLINK("#'Celular'!A1","Celular") -> Celular | D3: =HYPERLINK("#'Lançamentos'!A1","Lançamentos") -> Lançamentos | E3: Contas | F3: =HYPERLINK("#'Cartão'!A1","Cartão") -> Cartão | G3: =HYPERLINK("#'Dívidas'!A1","Dívidas") -> Dívidas | H3: =HYPERLINK("#'Categorias'!A1","Categorias") -> Categorias | I3: =HYPERLINK("#'Metas'!A1","Metas") -> Metas | J3: =HYPERLINK("#'Patrimônio'!A1","Patrimônio") -> Patrimônio | K3: =HYPERLINK("#'Simulador'!A1","Simulador") -> Simulador | L3: =HYPERLINK("#'Resumo'!A1","Resumo") -> Resumo | M3: =HYPERLINK("#'Como usar'!A1","Ajuda") -> Ajuda
B5: Mês | C5: 46296
B7: Conta | C7: Categoria | D7: Valor previsto | E7: Dia do vencimento | F7: Pagamento | G7: Vence em | H7: Pago no mês | I7: Situação | K7: Resumo do mês
B8: Aluguel | C8: Moradia | D8: 1200 | E8: 10 | F8: Boleto | G8: =DATE(YEAR($C$5),MONTH($C$5),MIN(tbContas[[#This Row],[Dia do vencimento]],DAY(EOMONTH($C$5,0)))) -> 46305 | H8: =SUMIFS(tbLancamentos[Valor],tbLancamentos[Mês],$C$5,tbLancamentos[Descrição],tbContas[[#This Row],[Conta]]) -> 1200 | I8: =IF(tbContas[[#This Row],[Pago no mês]]>0,"✓ Paga",IF(TODAY()>tbContas[[#This Row],[Vence em]],"⚠ Vencida","Pendente")) -> ✓ Paga | K8: Total previsto | L8: =SUM(tbContas[Valor previsto]) -> 1991.3
B9: Conta de luz | C9: Contas da casa | D9: 180 | E9: 12 | F9: Boleto | G9: =DATE(YEAR($C$5),MONTH($C$5),MIN(tbContas[[#This Row],[Dia do vencimento]],DAY(EOMONTH($C$5,0)))) -> 46307 | H9: =SUMIFS(tbLancamentos[Valor],tbLancamentos[Mês],$C$5,tbLancamentos[Descrição],tbContas[[#This Row],[Conta]]) -> 165.63 | I9: =IF(tbContas[[#This Row],[Pago no mês]]>0,"✓ Paga",IF(TODAY()>tbContas[[#This Row],[Vence em]],"⚠ Vencida","Pendente")) -> ✓ Paga | K9: Já pago | L9: =SUM(tbContas[Pago no mês]) -> 1901.55
B10: Conta de água | C10: Contas da casa | D10: 80 | E10: 15 | F10: Boleto | G10: =DATE(YEAR($C$5),MONTH($C$5),MIN(tbContas[[#This Row],[Dia do vencimento]],DAY(EOMONTH($C$5,0)))) -> 46310 | H10: =SUMIFS(tbLancamentos[Valor],tbLancamentos[Mês],$C$5,tbLancamentos[Descrição],tbContas[[#This Row],[Conta]]) -> 79.62 | I10: =IF(tbContas[[#This Row],[Pago no mês]]>0,"✓ Paga",IF(TODAY()>tbContas[[#This Row],[Vence em]],"⚠ Vencida","Pendente")) -> ✓ Paga | K10: Falta pagar | L10: =SUMIFS(tbContas[Valor previsto],tbContas[Situação],"<>✓ Paga") -> 75
B11: Internet | C11: Contas da casa | D11: 99.9 | E11: 18 | F11: Débito | G11: =DATE(YEAR($C$5),MONTH($C$5),MIN(tbContas[[#This Row],[Dia do vencimento]],DAY(EOMONTH($C$5,0)))) -> 46313 | H11: =SUMIFS(tbLancamentos[Valor],tbLancamentos[Mês],$C$5,tbLancamentos[Descrição],tbContas[[#This Row],[Conta]]) -> 99.9 | I11: =IF(tbContas[[#This Row],[Pago no mês]]>0,"✓ Paga",IF(TODAY()>tbContas[[#This Row],[Vence em]],"⚠ Vencida","Pendente")) -> ✓ Paga | K11: Contas pagas | L11: =COUNTIF(tbContas[Situação],"✓ Paga")&" de "&ROWS(tbContas[]) -> 10 de 12
B12: Plano de celular | C12: Contas da casa | D12: 49.9 | E12: 20 | F12: Cartão de crédito | G12: =DATE(YEAR($C$5),MONTH($C$5),MIN(tbContas[[#This Row],[Dia do vencimento]],DAY(EOMONTH($C$5,0)))) -> 46315 | H12: =SUMIFS(tbLancamentos[Valor],tbLancamentos[Mês],$C$5,tbLancamentos[Descrição],tbContas[[#This Row],[Conta]]) -> 49.9 | I12: =IF(tbContas[[#This Row],[Pago no mês]]>0,"✓ Paga",IF(TODAY()>tbContas[[#This Row],[Vence em]],"⚠ Vencida","Pendente")) -> ✓ Paga | K12: Contas vencidas | L12: =COUNTIF(tbContas[Situação],"⚠ Vencida") -> 1
B13: Academia | C13: Saúde | D13: 99.9 | E13: 8 | F13: Cartão de crédito | G13: =DATE(YEAR($C$5),MONTH($C$5),MIN(tbContas[[#This Row],[Dia do vencimento]],DAY(EOMONTH($C$5,0)))) -> 46303 | H13: =SUMIFS(tbLancamentos[Valor],tbLancamentos[Mês],$C$5,tbLancamentos[Descrição],tbContas[[#This Row],[Conta]]) -> 99.9 | I13: =IF(tbContas[[#This Row],[Pago no mês]]>0,"✓ Paga",IF(TODAY()>tbContas[[#This Row],[Vence em]],"⚠ Vencida","Pendente")) -> ✓ Paga
B14: Plano odontológico | C14: Saúde | D14: 59.9 | E14: 8 | F14: Boleto | G14: =DATE(YEAR($C$5),MONTH($C$5),MIN(tbContas[[#This Row],[Dia do vencimento]],DAY(EOMONTH($C$5,0)))) -> 46303 | H14: =SUMIFS(tbLancamentos[Valor],tbLancamentos[Mês],$C$5,tbLancamentos[Descrição],tbContas[[#This Row],[Conta]]) -> 59.9 | I14: =IF(tbContas[[#This Row],[Pago no mês]]>0,"✓ Paga",IF(TODAY()>tbContas[[#This Row],[Vence em]],"⚠ Vencida","Pendente")) -> ✓ Paga | K14: Dica: use na aba Lançamentos a mesma descrição
B15: Netflix | C15: Assinaturas | D15: 44.9 | E15: 14 | F15: Cartão de crédito | G15: =DATE(YEAR($C$5),MONTH($C$5),MIN(tbContas[[#This Row],[Dia do vencimento]],DAY(EOMONTH($C$5,0)))) -> 46309 | H15: =SUMIFS(tbLancamentos[Valor],tbLancamentos[Mês],$C$5,tbLancamentos[Descrição],tbContas[[#This Row],[Conta]]) -> 44.9 | I15: =IF(tbContas[[#This Row],[Pago no mês]]>0,"✓ Paga",IF(TODAY()>tbContas[[#This Row],[Vence em]],"⚠ Vencida","Pendente")) -> ✓ Paga | K15: da conta (ex.: "Conta de luz") para ela
B16: Spotify | C16: Assinaturas | D16: 21.9 | E16: 14 | F16: Cartão de crédito | G16: =DATE(YEAR($C$5),MONTH($C$5),MIN(tbContas[[#This Row],[Dia do vencimento]],DAY(EOMONTH($C$5,0)))) -> 46309 | H16: =SUMIFS(tbLancamentos[Valor],tbLancamentos[Mês],$C$5,tbLancamentos[Descrição],tbContas[[#This Row],[Conta]]) -> 21.9 | I16: =IF(tbContas[[#This Row],[Pago no mês]]>0,"✓ Paga",IF(TODAY()>tbContas[[#This Row],[Vence em]],"⚠ Vencida","Pendente")) -> ✓ Paga | K16: aparecer como paga.
B17: Curso online | C17: Educação | D17: 79.9 | E17: 20 | F17: Cartão de crédito | G17: =DATE(YEAR($C$5),MONTH($C$5),MIN(tbContas[[#This Row],[Dia do vencimento]],DAY(EOMONTH($C$5,0)))) -> 46315 | H17: =SUMIFS(tbLancamentos[Valor],tbLancamentos[Mês],$C$5,tbLancamentos[Descrição],tbContas[[#This Row],[Conta]]) -> 79.9 | I17: =IF(tbContas[[#This Row],[Pago no mês]]>0,"✓ Paga",IF(TODAY()>tbContas[[#This Row],[Vence em]],"⚠ Vencida","Pendente")) -> ✓ Paga
B18: Doação mensal | C18: Outros | D18: 30 | E18: 5 | F18: Pix | G18: =DATE(YEAR($C$5),MONTH($C$5),MIN(tbContas[[#This Row],[Dia do vencimento]],DAY(EOMONTH($C$5,0)))) -> 46300 | H18: =SUMIFS(tbLancamentos[Valor],tbLancamentos[Mês],$C$5,tbLancamentos[Descrição],tbContas[[#This Row],[Conta]]) -> 0 | I18: =IF(tbContas[[#This Row],[Pago no mês]]>0,"✓ Paga",IF(TODAY()>tbContas[[#This Row],[Vence em]],"⚠ Vencida","Pendente")) -> ⚠ Vencida
B19: Seguro residencial | C19: Moradia | D19: 45 | E19: 28 | F19: Débito | G19: =DATE(YEAR($C$5),MONTH($C$5),MIN(tbContas[[#This Row],[Dia do vencimento]],DAY(EOMONTH($C$5,0)))) -> 46323 | H19: =SUMIFS(tbLancamentos[Valor],tbLancamentos[Mês],$C$5,tbLancamentos[Descrição],tbContas[[#This Row],[Conta]]) -> 0 | I19: =IF(tbContas[[#This Row],[Pago no mês]]>0,"✓ Paga",IF(TODAY()>tbContas[[#This Row],[Vence em]],"⚠ Vencida","Pendente")) -> Pendente

Sheet Cartão
B1: Cartão de crédito
B2: Compras parceladas e próximas faturas. A cada mês, lance a parcela em Lançamentos com a mesma descrição da compra para ela aparecer como lançada.
B3: =HYPERLINK("#'Painel'!A1","Painel") -> Painel | C3: =HYPERLINK("#'Celular'!A1","Celular") -> Celular | D3: =HYPERLINK("#'Lançamentos'!A1","Lançamentos") -> Lançamentos | E3: =HYPERLINK("#'Contas fixas'!A1","Contas") -> Contas | F3: Cartão | G3: =HYPERLINK("#'Dívidas'!A1","Dívidas") -> Dívidas | H3: =HYPERLINK("#'Categorias'!A1","Categorias") -> Categorias | I3: =HYPERLINK("#'Metas'!A1","Metas") -> Metas | J3: =HYPERLINK("#'Patrimônio'!A1","Patrimônio") -> Patrimônio | K3: =HYPERLINK("#'Simulador'!A1","Simulador") -> Simulador | L3: =HYPERLINK("#'Resumo'!A1","Resumo") -> Resumo | M3: =HYPERLINK("#'Como usar'!A1","Ajuda") -> Ajuda
B5: Mês | C5: 46296
B7: Cartão | C7: Fecha dia | D7: Vence dia | E7: Limite | G7: Cartão | H7: Parcelas no mês | I7: Ainda a pagar | J7: Limite | K7: Limite livre | M7: Fatura | N7: =IFERROR(INDEX(tbCartoes[Cartão],COLUMNS($N7:N7)),"") -> Nubank | O7: =IFERROR(INDEX(tbCartoes[Cartão],COLUMNS($N7:O7)),"") -> Inter | P7: =IFERROR(INDEX(tbCartoes[Cartão],COLUMNS($N7:P7)),"") | Q7: Total
B8: Nubank | C8: 3 | D8: 10 | E8: 6000 | G8: =IFERROR(INDEX(tbCartoes[Cartão],ROWS(G$8:G8)),"") -> Nubank | H8: =IF($G8="","",SUMIFS(tbParcelas[Valor no mês],tbParcelas[Cartão],$G8)) -> 720 | I8: =IF($G8="","",H8+SUMIFS(tbParcelas[A pagar depois],tbParcelas[Cartão],$G8)) -> 5520 | J8: =IF($G8="","",INDEX(tbCartoes[Limite],MATCH($G8,tbCartoes[Cartão],0))) -> 6000 | K8: =IF($G8="","",J8-I8) -> 480 | M8: =$C$5 -> 46296 | N8: =IF(N$7="","",SUMPRODUCT(tbParcelas[Valor da parcela]*(tbParcelas[Cartão]=N$7)*(tbParcelas[1ª fatura]<=$M8)*(tbParcelas[Última fatura]>=$M8))) -> 720 | O8: =IF(O$7="","",SUMPRODUCT(tbParcelas[Valor da parcela]*(tbParcelas[Cartão]=O$7)*(tbParcelas[1ª fatura]<=$M8)*(tbParcelas[Última fatura]>=$M8))) -> 200 | P8: =IF(P$7="","",SUMPRODUCT(tbParcelas[Valor da parcela]*(tbParcelas[Cartão]=P$7)*(tbParcelas[1ª fatura]<=$M8)*(tbParcelas[Última fatura]>=$M8))) | Q8: =SUM(N8:P8) -> 920
B9: Inter | C9: 25 | D9: 5 | E9: 3000 | G9: =IFERROR(INDEX(tbCartoes[Cartão],ROWS(G$8:G9)),"") -> Inter | H9: =IF($G9="","",SUMIFS(tbParcelas[Valor no mês],tbParcelas[Cartão],$G9)) -> 200 | I9: =IF($G9="","",H9+SUMIFS(tbParcelas[A pagar depois],tbParcelas[Cartão],$G9)) -> 1200 | J9: =IF($G9="","",INDEX(tbCartoes[Limite],MATCH($G9,tbCartoes[Cartão],0))) -> 3000 | K9: =IF($G9="","",J9-I9) -> 1800 | M9: =EDATE(M8,1) -> 46327 | N9: =IF(N$7="","",SUMPRODUCT(tbParcelas[Valor da parcela]*(tbParcelas[Cartão]=N$7)*(tbParcelas[1ª fatura]<=$M9)*(tbParcelas[Última fatura]>=$M9))) -> 720 | O9: =IF(O$7="","",SUMPRODUCT(tbParcelas[Valor da parcela]*(tbParcelas[Cartão]=O$7)*(tbParcelas[1ª fatura]<=$M9)*(tbParcelas[Última fatura]>=$M9))) -> 200 | P9: =IF(P$7="","",SUMPRODUCT(tbParcelas[Valor da parcela]*(tbParcelas[Cartão]=P$7)*(tbParcelas[1ª fatura]<=$M9)*(tbParcelas[Última fatura]>=$M9))) | Q9: =SUM(N9:P9) -> 920
G10: =IFERROR(INDEX(tbCartoes[Cartão],ROWS(G$8:G10)),"") | H10: =IF($G10="","",SUMIFS(tbParcelas[Valor no mês],tbParcelas[Cartão],$G10)) | I10: =IF($G10="","",H10+SUMIFS(tbParcelas[A pagar depois],tbParcelas[Cartão],$G10)) | J10: =IF($G10="","",INDEX(tbCartoes[Limite],MATCH($G10,tbCartoes[Cartão],0))) | K10: =IF($G10="","",J10-I10) | M10: =EDATE(M9,1) -> 46357 | N10: =IF(N$7="","",SUMPRODUCT(tbParcelas[Valor da parcela]*(tbParcelas[Cartão]=N$7)*(tbParcelas[1ª fatura]<=$M10)*(tbParcelas[Última fatura]>=$M10))) -> 720 | O10: =IF(O$7="","",SUMPRODUCT(tbParcelas[Valor da parcela]*(tbParcelas[Cartão]=O$7)*(tbParcelas[1ª fatura]<=$M10)*(tbParcelas[Última fatura]>=$M10))) -> 200 | P10: =IF(P$7="","",SUMPRODUCT(tbParcelas[Valor da parcela]*(tbParcelas[Cartão]=P$7)*(tbParcelas[1ª fatura]<=$M10)*(tbParcelas[Última fatura]>=$M10))) | Q10: =SUM(N10:P10) -> 920
G11: Total | H11: =SUM(H8:H10) -> 920 | I11: =SUM(I8:I10) -> 6720 | J11: =SUM(J8:J10) -> 9000 | K11: =SUM(K8:K10) -> 2280 | M11: =EDATE(M10,1) -> 46388 | N11: =IF(N$7="","",SUMPRODUCT(tbParcelas[Valor da parcela]*(tbParcelas[Cartão]=N$7)*(tbParcelas[1ª fatura]<=$M11)*(tbParcelas[Última fatura]>=$M11))) -> 560 | O11: =IF(O$7="","",SUMPRODUCT(tbParcelas[Valor da parcela]*(tbParcelas[Cartão]=O$7)*(tbParcelas[1ª fatura]<=$M11)*(tbParcelas[Última fatura]>=$M11))) -> 200 | P11: =IF(P$7="","",SUMPRODUCT(tbParcelas[Valor da parcela]*(tbParcelas[Cartão]=P$7)*(tbParcelas[1ª fatura]<=$M11)*(tbParcelas[Última fatura]>=$M11))) | Q11: =SUM(N11:P11) -> 760
M12: =EDATE(M11,1) -> 46419 | N12: =IF(N$7="","",SUMPRODUCT(tbParcelas[Valor da parcela]*(tbParcelas[Cartão]=N$7)*(tbParcelas[1ª fatura]<=$M12)*(tbParcelas[Última fatura]>=$M12))) -> 560 | O12: =IF(O$7="","",SUMPRODUCT(tbParcelas[Valor da parcela]*(tbParcelas[Cartão]=O$7)*(tbParcelas[1ª fatura]<=$M12)*(tbParcelas[Última fatura]>=$M12))) -> 200 | P12: =IF(P$7="","",SUMPRODUCT(tbParcelas[Valor da parcela]*(tbParcelas[Cartão]=P$7)*(tbParcelas[1ª fatura]<=$M12)*(tbParcelas[Última fatura]>=$M12))) | Q12: =SUM(N12:P12) -> 760
G13: Ainda a pagar = parcelas do mês + parcelas dos meses seguintes. Limite livre não desconta as compras à vista do mês. | M13: =EDATE(M12,1) -> 46447 | N13: =IF(N$7="","",SUMPRODUCT(tbParcelas[Valor da parcela]*(tbParcelas[Cartão]=N$7)*(tbParcelas[1ª fatura]<=$M13)*(tbParcelas[Última fatura]>=$M13))) -> 560 | O13: =IF(O$7="","",SUMPRODUCT(tbParcelas[Valor da parcela]*(tbParcelas[Cartão]=O$7)*(tbParcelas[1ª fatura]<=$M13)*(tbParcelas[Última fatura]>=$M13))) -> 200 | P13: =IF(P$7="","",SUMPRODUCT(tbParcelas[Valor da parcela]*(tbParcelas[Cartão]=P$7)*(tbParcelas[1ª fatura]<=$M13)*(tbParcelas[Última fatura]>=$M13))) | Q13: =SUM(N13:P13) -> 760
M14: =EDATE(M13,1) -> 46478 | N14: =IF(N$7="","",SUMPRODUCT(tbParcelas[Valor da parcela]*(tbParcelas[Cartão]=N$7)*(tbParcelas[1ª fatura]<=$M14)*(tbParcelas[Última fatura]>=$M14))) -> 560 | O14: =IF(O$7="","",SUMPRODUCT(tbParcelas[Valor da parcela]*(tbParcelas[Cartão]=O$7)*(tbParcelas[1ª fatura]<=$M14)*(tbParcelas[Última fatura]>=$M14))) -> 0 | P14: =IF(P$7="","",SUMPRODUCT(tbParcelas[Valor da parcela]*(tbParcelas[Cartão]=P$7)*(tbParcelas[1ª fatura]<=$M14)*(tbParcelas[Última fatura]>=$M14))) | Q14: =SUM(N14:P14) -> 560
M15: =EDATE(M14,1) -> 46508 | N15: =IF(N$7="","",SUMPRODUCT(tbParcelas[Valor da parcela]*(tbParcelas[Cartão]=N$7)*(tbParcelas[1ª fatura]<=$M15)*(tbParcelas[Última fatura]>=$M15))) -> 560 | O15: =IF(O$7="","",SUMPRODUCT(tbParcelas[Valor da parcela]*(tbParcelas[Cartão]=O$7)*(tbParcelas[1ª fatura]<=$M15)*(tbParcelas[Última fatura]>=$M15))) -> 0 | P15: =IF(P$7="","",SUMPRODUCT(tbParcelas[Valor da parcela]*(tbParcelas[Cartão]=P$7)*(tbParcelas[1ª fatura]<=$M15)*(tbParcelas[Última fatura]>=$M15))) | Q15: =SUM(N15:P15) -> 560
M16: =EDATE(M15,1) -> 46539 | N16: =IF(N$7="","",SUMPRODUCT(tbParcelas[Valor da parcela]*(tbParcelas[Cartão]=N$7)*(tbParcelas[1ª fatura]<=$M16)*(tbParcelas[Última fatura]>=$M16))) -> 560 | O16: =IF(O$7="","",SUMPRODUCT(tbParcelas[Valor da parcela]*(tbParcelas[Cartão]=O$7)*(tbParcelas[1ª fatura]<=$M16)*(tbParcelas[Última fatura]>=$M16))) -> 0 | P16: =IF(P$7="","",SUMPRODUCT(tbParcelas[Valor da parcela]*(tbParcelas[Cartão]=P$7)*(tbParcelas[1ª fatura]<=$M16)*(tbParcelas[Última fatura]>=$M16))) | Q16: =SUM(N16:P16) -> 560
M17: =EDATE(M16,1) -> 46569 | N17: =IF(N$7="","",SUMPRODUCT(tbParcelas[Valor da parcela]*(tbParcelas[Cartão]=N$7)*(tbParcelas[1ª fatura]<=$M17)*(tbParcelas[Última fatura]>=$M17))) -> 0 | O17: =IF(O$7="","",SUMPRODUCT(tbParcelas[Valor da parcela]*(tbParcelas[Cartão]=O$7)*(tbParcelas[1ª fatura]<=$M17)*(tbParcelas[Última fatura]>=$M17))) -> 0 | P17: =IF(P$7="","",SUMPRODUCT(tbParcelas[Valor da parcela]*(tbParcelas[Cartão]=P$7)*(tbParcelas[1ª fatura]<=$M17)*(tbParcelas[Última fatura]>=$M17))) | Q17: =SUM(N17:P17) -> 0
M18: =EDATE(M17,1) -> 46600 | N18: =IF(N$7="","",SUMPRODUCT(tbParcelas[Valor da parcela]*(tbParcelas[Cartão]=N$7)*(tbParcelas[1ª fatura]<=$M18)*(tbParcelas[Última fatura]>=$M18))) -> 0 | O18: =IF(O$7="","",SUMPRODUCT(tbParcelas[Valor da parcela]*(tbParcelas[Cartão]=O$7)*(tbParcelas[1ª fatura]<=$M18)*(tbParcelas[Última fatura]>=$M18))) -> 0 | P18: =IF(P$7="","",SUMPRODUCT(tbParcelas[Valor da parcela]*(tbParcelas[Cartão]=P$7)*(tbParcelas[1ª fatura]<=$M18)*(tbParcelas[Última fatura]>=$M18))) | Q18: =SUM(N18:P18) -> 0
M19: =EDATE(M18,1) -> 46631 | N19: =IF(N$7="","",SUMPRODUCT(tbParcelas[Valor da parcela]*(tbParcelas[Cartão]=N$7)*(tbParcelas[1ª fatura]<=$M19)*(tbParcelas[Última fatura]>=$M19))) -> 0 | O19: =IF(O$7="","",SUMPRODUCT(tbParcelas[Valor da parcela]*(tbParcelas[Cartão]=O$7)*(tbParcelas[1ª fatura]<=$M19)*(tbParcelas[Última fatura]>=$M19))) -> 0 | P19: =IF(P$7="","",SUMPRODUCT(tbParcelas[Valor da parcela]*(tbParcelas[Cartão]=P$7)*(tbParcelas[1ª fatura]<=$M19)*(tbParcelas[Última fatura]>=$M19))) | Q19: =SUM(N19:P19) -> 0
B21: Compras parceladas
B22: Data da compra | C22: Descrição | D22: Categoria | E22: Cartão | F22: Valor total | G22: Parcelas | H22: Valor da parcela | I22: 1ª fatura | J22: Última fatura | K22: Parcela do mês | L22: Valor no mês | M22: A pagar depois | N22: Situação
B23: 46183 | C23: Celular novo | D23: Compras | E23: Nubank | F23: 2400 | G23: 12 | H23: =IF(N(tbParcelas[[#This Row],[Parcelas]])=0,0,tbParcelas[[#This Row],[Valor total]]/tbParcelas[[#This Row],[Parcelas]]) -> 200 | I23: =IFERROR(EDATE(DATE(YEAR(tbParcelas[[#This Row],[Data da compra]]),MONTH(tbParcelas[[#This Row],[Data da compra]]),1),IF(DAY(tbParcelas[[#This Row],[Data da compra]])>=INDEX(tbCartoes[Fecha dia],MATCH(tbParcelas[[#This Row],[Cartão]],tbCartoes[Cartão],0)),1,0)+IF(INDEX(tbCartoes[Vence dia],MATCH(tbParcelas[[#This Row],[Cartão]],tbCartoes[Cartão],0))<=INDEX(tbCartoes[Fecha dia],MATCH(tbParcelas[[#This Row],[Cartão]],tbCartoes[Cartão],0)),1,0)),"") -> 46204 | J23: =IF(tbParcelas[[#This Row],[1ª fatura]]="","",EDATE(tbParcelas[[#This Row],[1ª fatura]],tbParcelas[[#This Row],[Parcelas]]-1)) -> 46539 | K23: =IF(tbParcelas[[#This Row],[1ª fatura]]="","",IF(AND($C$5>=tbParcelas[[#This Row],[1ª fatura]],$C$5<=tbParcelas[[#This Row],[Última fatura]]),((YEAR($C$5)-YEAR(tbParcelas[[#This Row],[1ª fatura]]))*12+MONTH($C$5)-MONTH(tbParcelas[[#This Row],[1ª fatura]])+1)&" de "&tbParcelas[[#This Row],[Parcelas]],"—")) -> 4 de 12 | L23: =IF(tbParcelas[[#This Row],[1ª fatura]]="",0,IF(AND($C$5>=tbParcelas[[#This Row],[1ª fatura]],$C$5<=tbParcelas[[#This Row],[Última fatura]]),tbParcelas[[#This Row],[Valor da parcela]],0)) -> 200 | M23: =IF(tbParcelas[[#This Row],[1ª fatura]]="",0,tbParcelas[[#This Row],[Valor da parcela]]*MAX(0,MIN(tbParcelas[[#This Row],[Parcelas]],(YEAR(tbParcelas[[#This Row],[Última fatura]])-YEAR($C$5))*12+MONTH(tbParcelas[[#This Row],[Última fatura]])-MONTH($C$5)))) -> 1600 | N23: =IF(tbParcelas[[#This Row],[Valor no mês]]=0,"—",IF(SUMIFS(tbLancamentos[Valor],tbLancamentos[Mês],$C$5,tbLancamentos[Descrição],tbParcelas[[#This Row],[Descrição]])>0,"✓ Lançada","Lançar no mês")) -> Lançar no mês
B24: 46249 | C24: Geladeira | D24: Compras | E24: Nubank | F24: 3600 | G24: 10 | H24: =IF(N(tbParcelas[[#This Row],[Parcelas]])=0,0,tbParcelas[[#This Row],[Valor total]]/tbParcelas[[#This Row],[Parcelas]]) -> 360 | I24: =IFERROR(EDATE(DATE(YEAR(tbParcelas[[#This Row],[Data da compra]]),MONTH(tbParcelas[[#This Row],[Data da compra]]),1),IF(DAY(tbParcelas[[#This Row],[Data da compra]])>=INDEX(tbCartoes[Fecha dia],MATCH(tbParcelas[[#This Row],[Cartão]],tbCartoes[Cartão],0)),1,0)+IF(INDEX(tbCartoes[Vence dia],MATCH(tbParcelas[[#This Row],[Cartão]],tbCartoes[Cartão],0))<=INDEX(tbCartoes[Fecha dia],MATCH(tbParcelas[[#This Row],[Cartão]],tbCartoes[Cartão],0)),1,0)),"") -> 46266 | J24: =IF(tbParcelas[[#This Row],[1ª fatura]]="","",EDATE(tbParcelas[[#This Row],[1ª fatura]],tbParcelas[[#This Row],[Parcelas]]-1)) -> 46539 | K24: =IF(tbParcelas[[#This Row],[1ª fatura]]="","",IF(AND($C$5>=tbParcelas[[#This Row],[1ª fatura]],$C$5<=tbParcelas[[#This Row],[Última fatura]]),((YEAR($C$5)-YEAR(tbParcelas[[#This Row],[1ª fatura]]))*12+MONTH($C$5)-MONTH(tbParcelas[[#This Row],[1ª fatura]])+1)&" de "&tbParcelas[[#This Row],[Parcelas]],"—")) -> 2 de 10 | L24: =IF(tbParcelas[[#This Row],[1ª fatura]]="",0,IF(AND($C$5>=tbParcelas[[#This Row],[1ª fatura]],$C$5<=tbParcelas[[#This Row],[Última fatura]]),tbParcelas[[#This Row],[Valor da parcela]],0)) -> 360 | M24: =IF(tbParcelas[[#This Row],[1ª fatura]]="",0,tbParcelas[[#This Row],[Valor da parcela]]*MAX(0,MIN(tbParcelas[[#This Row],[Parcelas]],(YEAR(tbParcelas[[#This Row],[Última fatura]])-YEAR($C$5))*12+MONTH(tbParcelas[[#This Row],[Última fatura]])-MONTH($C$5)))) -> 2880 | N24: =IF(tbParcelas[[#This Row],[Valor no mês]]=0,"—",IF(SUMIFS(tbLancamentos[Valor],tbLancamentos[Mês],$C$5,tbLancamentos[Descrição],tbParcelas[[#This Row],[Descrição]])>0,"✓ Lançada","Lançar no mês")) -> Lançar no mês
B25: 46285 | C25: Curso de inglês | D25: Educação | E25: Inter | F25: 1200 | G25: 6 | H25: =IF(N(tbParcelas[[#This Row],[Parcelas]])=0,0,tbParcelas[[#This Row],[Valor total]]/tbParcelas[[#This Row],[Parcelas]]) -> 200 | I25: =IFERROR(EDATE(DATE(YEAR(tbParcelas[[#This Row],[Data da compra]]),MONTH(tbParcelas[[#This Row],[Data da compra]]),1),IF(DAY(tbParcelas[[#This Row],[Data da compra]])>=INDEX(tbCartoes[Fecha dia],MATCH(tbParcelas[[#This Row],[Cartão]],tbCartoes[Cartão],0)),1,0)+IF(INDEX(tbCartoes[Vence dia],MATCH(tbParcelas[[#This Row],[Cartão]],tbCartoes[Cartão],0))<=INDEX(tbCartoes[Fecha dia],MATCH(tbParcelas[[#This Row],[Cartão]],tbCartoes[Cartão],0)),1,0)),"") -> 46296 | J25: =IF(tbParcelas[[#This Row],[1ª fatura]]="","",EDATE(tbParcelas[[#This Row],[1ª fatura]],tbParcelas[[#This Row],[Parcelas]]-1)) -> 46447 | K25: =IF(tbParcelas[[#This Row],[1ª fatura]]="","",IF(AND($C$5>=tbParcelas[[#This Row],[1ª fatura]],$C$5<=tbParcelas[[#This Row],[Última fatura]]),((YEAR($C$5)-YEAR(tbParcelas[[#This Row],[1ª fatura]]))*12+MONTH($C$5)-MONTH(tbParcelas[[#This Row],[1ª fatura]])+1)&" de "&tbParcelas[[#This Row],[Parcelas]],"—")) -> 1 de 6 | L25: =IF(tbParcelas[[#This Row],[1ª fatura]]="",0,IF(AND($C$5>=tbParcelas[[#This Row],[1ª fatura]],$C$5<=tbParcelas[[#This Row],[Última fatura]]),tbParcelas[[#This Row],[Valor da parcela]],0)) -> 200 | M25: =IF(tbParcelas[[#This Row],[1ª fatura]]="",0,tbParcelas[[#This Row],[Valor da parcela]]*MAX(0,MIN(tbParcelas[[#This Row],[Parcelas]],(YEAR(tbParcelas[[#This Row],[Última fatura]])-YEAR($C$5))*12+MONTH(tbParcelas[[#This Row],[Última fatura]])-MONTH($C$5)))) -> 1000 | N25: =IF(tbParcelas[[#This Row],[Valor no mês]]=0,"—",IF(SUMIFS(tbLancamentos[Valor],tbLancamentos[Mês],$C$5,tbLancamentos[Descrição],tbParcelas[[#This Row],[Descrição]])>0,"✓ Lançada","Lançar no mês")) -> Lançar no mês
B26: 46297 | C26: Tênis de corrida | D26: Compras | E26: Nubank | F26: 480 | G26: 3 | H26: =IF(N(tbParcelas[[#This Row],[Parcelas]])=0,0,tbParcelas[[#This Row],[Valor total]]/tbParcelas[[#This Row],[Parcelas]]) -> 160 | I26: =IFERROR(EDATE(DATE(YEAR(tbParcelas[[#This Row],[Data da compra]]),MONTH(tbParcelas[[#This Row],[Data da compra]]),1),IF(DAY(tbParcelas[[#This Row],[Data da compra]])>=INDEX(tbCartoes[Fecha dia],MATCH(tbParcelas[[#This Row],[Cartão]],tbCartoes[Cartão],0)),1,0)+IF(INDEX(tbCartoes[Vence dia],MATCH(tbParcelas[[#This Row],[Cartão]],tbCartoes[Cartão],0))<=INDEX(tbCartoes[Fecha dia],MATCH(tbParcelas[[#This Row],[Cartão]],tbCartoes[Cartão],0)),1,0)),"") -> 46296 | J26: =IF(tbParcelas[[#This Row],[1ª fatura]]="","",EDATE(tbParcelas[[#This Row],[1ª fatura]],tbParcelas[[#This Row],[Parcelas]]-1)) -> 46357 | K26: =IF(tbParcelas[[#This Row],[1ª fatura]]="","",IF(AND($C$5>=tbParcelas[[#This Row],[1ª fatura]],$C$5<=tbParcelas[[#This Row],[Última fatura]]),((YEAR($C$5)-YEAR(tbParcelas[[#This Row],[1ª fatura]]))*12+MONTH($C$5)-MONTH(tbParcelas[[#This Row],[1ª fatura]])+1)&" de "&tbParcelas[[#This Row],[Parcelas]],"—")) -> 1 de 3 | L26: =IF(tbParcelas[[#This Row],[1ª fatura]]="",0,IF(AND($C$5>=tbParcelas[[#This Row],[1ª fatura]],$C$5<=tbParcelas[[#This Row],[Última fatura]]),tbParcelas[[#This Row],[Valor da parcela]],0)) -> 160 | M26: =IF(tbParcelas[[#This Row],[1ª fatura]]="",0,tbParcelas[[#This Row],[Valor da parcela]]*MAX(0,MIN(tbParcelas[[#This Row],[Parcelas]],(YEAR(tbParcelas[[#This Row],[Última fatura]])-YEAR($C$5))*12+MONTH(tbParcelas[[#This Row],[Última fatura]])-MONTH($C$5)))) -> 320 | N26: =IF(tbParcelas[[#This Row],[Valor no mês]]=0,"—",IF(SUMIFS(tbLancamentos[Valor],tbLancamentos[Mês],$C$5,tbLancamentos[Descrição],tbParcelas[[#This Row],[Descrição]])>0,"✓ Lançada","Lançar no mês")) -> Lançar no mês

Sheet Dívidas
B1: Dívidas e empréstimos
B2: Financiamentos, empréstimos e parcelamentos com juros. Atualize "Parcelas pagas" a cada mês.
B3: =HYPERLINK("#'Painel'!A1","Painel") -> Painel | C3: =HYPERLINK("#'Celular'!A1","Celular") -> Celular | D3: =HYPERLINK("#'Lançamentos'!A1","Lançamentos") -> Lançamentos | E3: =HYPERLINK("#'Contas fixas'!A1","Contas") -> Contas | F3: =HYPERLINK("#'Cartão'!A1","Cartão") -> Cartão | G3: Dívidas | H3: =HYPERLINK("#'Categorias'!A1","Categorias") -> Categorias | I3: =HYPERLINK("#'Metas'!A1","Metas") -> Metas | J3: =HYPERLINK("#'Patrimônio'!A1","Patrimônio") -> Patrimônio | K3: =HYPERLINK("#'Simulador'!A1","Simulador") -> Simulador | L3: =HYPERLINK("#'Resumo'!A1","Resumo") -> Resumo | M3: =HYPERLINK("#'Como usar'!A1","Ajuda") -> Ajuda
B5: Dívida | C5: Credor | D5: Valor contratado | E5: Juros ao mês | F5: Nº de parcelas | G5: Valor da parcela | H5: 1ª parcela | I5: Parcelas pagas | J5: Restantes | K5: Saldo devedor | L5: Total a pagar | M5: Juros a pagar | N5: Quitação | O5: Progresso | Q5: Dívida | R5: Já pago | S5: Falta pagar
B6: Financiamento do carro | C6: Banco do Brasil | D6: 18000 | E6: 0.0129 | F6: 36 | G6: 640 | H6: 45726 | I6: 19 | J6: =MAX(0,tbDividas[[#This Row],[Nº de parcelas]]-tbDividas[[#This Row],[Parcelas pagas]]) -> 17 | K6: =IF(tbDividas[[#This Row],[Restantes]]=0,0,IF(N(tbDividas[[#This Row],[Juros ao mês]])=0,tbDividas[[#This Row],[Valor da parcela]]*tbDividas[[#This Row],[Restantes]],PV(tbDividas[[#This Row],[Juros ao mês]],tbDividas[[#This Row],[Restantes]],-tbDividas[[#This Row],[Valor da parcela]]))) -> 9713.7207 | L6: =tbDividas[[#This Row],[Valor da parcela]]*tbDividas[[#This Row],[Restantes]] -> 10880 | M6: =tbDividas[[#This Row],[Total a pagar]]-tbDividas[[#This Row],[Saldo devedor]] -> 1166.2793 | N6: =IF(tbDividas[[#This Row],[1ª parcela]]="","",EDATE(tbDividas[[#This Row],[1ª parcela]],tbDividas[[#This Row],[Nº de parcelas]]-1)) -> 46793 | O6: =IF(N(tbDividas[[#This Row],[Nº de parcelas]])=0,"",tbDividas[[#This Row],[Parcelas pagas]]/tbDividas[[#This Row],[Nº de parcelas]]) -> 0.52777778 | Q6: =IFERROR(INDEX(tbDividas[Dívida],ROWS(Q$6:Q6)),"") -> Financiamento do carro | R6: =IF($Q6="","",INDEX(tbDividas[Valor da parcela],ROWS(R$6:R6))*INDEX(tbDividas[Parcelas pagas],ROWS(R$6:R6))) -> 12160 | S6: =IF($Q6="","",INDEX(tbDividas[Total a pagar],ROWS(S$6:S6))) -> 10880
B7: Empréstimo pessoal | C7: Nubank | D7: 5000 | E7: 0.032 | F7: 12 | G7: 512 | H7: 46117 | I7: 7 | J7: =MAX(0,tbDividas[[#This Row],[Nº de parcelas]]-tbDividas[[#This Row],[Parcelas pagas]]) -> 5 | K7: =IF(tbDividas[[#This Row],[Restantes]]=0,0,IF(N(tbDividas[[#This Row],[Juros ao mês]])=0,tbDividas[[#This Row],[Valor da parcela]]*tbDividas[[#This Row],[Restantes]],PV(tbDividas[[#This Row],[Juros ao mês]],tbDividas[[#This Row],[Restantes]],-tbDividas[[#This Row],[Valor da parcela]]))) -> 2331.4799 | L7: =tbDividas[[#This Row],[Valor da parcela]]*tbDividas[[#This Row],[Restantes]] -> 2560 | M7: =tbDividas[[#This Row],[Total a pagar]]-tbDividas[[#This Row],[Saldo devedor]] -> 228.52011 | N7: =IF(tbDividas[[#This Row],[1ª parcela]]="","",EDATE(tbDividas[[#This Row],[1ª parcela]],tbDividas[[#This Row],[Nº de parcelas]]-1)) -> 46451 | O7: =IF(N(tbDividas[[#This Row],[Nº de parcelas]])=0,"",tbDividas[[#This Row],[Parcelas pagas]]/tbDividas[[#This Row],[Nº de parcelas]]) -> 0.58333333 | Q7: =IFERROR(INDEX(tbDividas[Dívida],ROWS(Q$6:Q7)),"") -> Empréstimo pessoal | R7: =IF($Q7="","",INDEX(tbDividas[Valor da parcela],ROWS(R$6:R7))*INDEX(tbDividas[Parcelas pagas],ROWS(R$6:R7))) -> 3584 | S7: =IF($Q7="","",INDEX(tbDividas[Total a pagar],ROWS(S$6:S7))) -> 2560
Q8: =IFERROR(INDEX(tbDividas[Dívida],ROWS(Q$6:Q8)),"") | R8: =IF($Q8="","",INDEX(tbDividas[Valor da parcela],ROWS(R$6:R8))*INDEX(tbDividas[Parcelas pagas],ROWS(R$6:R8))) | S8: =IF($Q8="","",INDEX(tbDividas[Total a pagar],ROWS(S$6:S8)))
B12: Resumo das dívidas
B13: Saldo devedor (quitar hoje) | C13: =SUM(tbDividas[Saldo devedor]) -> 12045.201
B14: Parcelas por mês | C14: =SUMIFS(tbDividas[Valor da parcela],tbDividas[Restantes],">0") -> 1152
B15: Total que ainda vai pagar | C15: =SUM(tbDividas[Total a pagar]) -> 13440
B16: Juros que ainda vai pagar | C16: =SUM(tbDividas[Juros a pagar]) -> 1394.7995
B17: % da renda nas parcelas | C17: =IFERROR(C14/AVERAGEIF(Resumo!$C$7:$C$18,">0"),"") -> 0.1883686
B18: Última quitação | C18: =IF(COUNT(tbDividas[Quitação])=0,"",MAX(tbDividas[Quitação])) -> 46793
B20: Saldo devedor = quanto custaria quitar tudo hoje (parcelas restantes trazidas a valor presente pelos juros).
B21: Quitar antes economiza os "juros que ainda vai pagar". Acima de 30% da renda em parcelas é sinal de alerta.

Sheet Categorias
B1: Categorias
B2: Ajuste nomes, tipo, grupo e orçamento. Categorias novas entram nas listas e no painel sozinhas.
B3: =HYPERLINK("#'Painel'!A1","Painel") -> Painel | C3: =HYPERLINK("#'Celular'!A1","Celular") -> Celular | D3: =HYPERLINK("#'Lançamentos'!A1","Lançamentos") -> Lançamentos | E3: =HYPERLINK("#'Contas fixas'!A1","Contas") -> Contas | F3: =HYPERLINK("#'Cartão'!A1","Cartão") -> Cartão | G3: =HYPERLINK("#'Dívidas'!A1","Dívidas") -> Dívidas | H3: Categorias | I3: =HYPERLINK("#'Metas'!A1","Metas") -> Metas | J3: =HYPERLINK("#'Patrimônio'!A1","Patrimônio") -> Patrimônio | K3: =HYPERLINK("#'Simulador'!A1","Simulador") -> Simulador | L3: =HYPERLINK("#'Resumo'!A1","Resumo") -> Resumo | M3: =HYPERLINK("#'Como usar'!A1","Ajuda") -> Ajuda
B5: Categoria | C5: Tipo | D5: Grupo | E5: Orçamento mensal | F5: Ordem | H5: Listas usadas nas validações
B6: Salário | C6: Receita | D6: Renda | F6: =IF(tbCategorias[[#This Row],[Tipo]]="Receita","",COUNTIF(INDEX(tbCategorias[Tipo],1):tbCategorias[[#This Row],[Tipo]],"<>Receita")) | H6: Tipos | I6: Grupos | J6: Pagamento
B7: Freelance | C7: Receita | D7: Renda | F7: =IF(tbCategorias[[#This Row],[Tipo]]="Receita","",COUNTIF(INDEX(tbCategorias[Tipo],1):tbCategorias[[#This Row],[Tipo]],"<>Receita")) | H7: Receita | I7: Renda | J7: Pix
B8: Outras receitas | C8: Receita | D8: Renda | F8: =IF(tbCategorias[[#This Row],[Tipo]]="Receita","",COUNTIF(INDEX(tbCategorias[Tipo],1):tbCategorias[[#This Row],[Tipo]],"<>Receita")) | H8: Despesa | I8: Essencial | J8: Cartão de crédito
B9: Moradia | C9: Despesa | D9: Essencial | E9: 1200 | F9: =IF(tbCategorias[[#This Row],[Tipo]]="Receita","",COUNTIF(INDEX(tbCategorias[Tipo],1):tbCategorias[[#This Row],[Tipo]],"<>Receita")) -> 1 | H9: Investimento | I9: Estilo de vida | J9: Débito
B10: Contas da casa | C10: Despesa | D10: Essencial | E10: 420 | F10: =IF(tbCategorias[[#This Row],[Tipo]]="Receita","",COUNTIF(INDEX(tbCategorias[Tipo],1):tbCategorias[[#This Row],[Tipo]],"<>Receita")) -> 2 | I10: Investimento | J10: Boleto
